#VRML_SIM R2019a utf8
WorldInfo {
}
Viewpoint {
  orientation 0.0716430754744752 0.9946263751875036 0.07473716289722022 4.664737950998876
  position -4.558445912380903 2.4178564842851773 0.01254082607176204
}
TexturedBackground {
}
TexturedBackgroundLight {
}
Floor {
}
DEF TOPANDBOTTOM Solid {
  translation 0 0.025 0
  children [
    Group {
      children [
        DEF S_BOTTOMBASE Shape {
          appearance DEF FIRSTCOLOR PBRAppearance {
            baseColor 0.9372549019607843 0.1607843137254902 0.1607843137254902
          }
          geometry Box {
            size 1 0.05 1
          }
        }
        DEF S_TOP Transform {
          translation 0 1.05 0
          children [
            Shape {
              appearance USE FIRSTCOLOR
              geometry Box {
                size 1 0.05 1
              }
            }
          ]
        }
      ]
    }
  ]
}
DEF FIRSTFACE Solid {
  translation 0.495 0.55 -0.45
  children [
    Group {
      children [
        Shape {
          appearance DEF SECONDCOlOR PBRAppearance {
            baseColor 0.9882352941176471 0.9137254901960784 0.30980392156862746
          }
          geometry Box {
            size 0.01 1 0.1
          }
        }
        Transform {
          translation 0 0 0.9
          children [
            Shape {
              appearance USE SECONDCOlOR
              geometry Box {
                size 0.01 1 0.1
              }
            }
          ]
        }
        Transform {
          translation 0 -0.45 0.45
          children [
            Shape {
              appearance USE SECONDCOlOR
              geometry Box {
                size 0.01 0.1 0.8
              }
            }
          ]
        }
        Transform {
          translation 0 0.45 0.45000000000000007
          children [
            Shape {
              appearance USE SECONDCOlOR
              geometry Box {
                size 0.01 0.1 0.8
              }
            }
          ]
        }
        Transform {
          translation 0 0 0.45
          rotation 1 0 0 0.7853996938995746
          children [
            Shape {
              appearance USE SECONDCOlOR
              geometry Box {
                size 0.01 1.34 0.07
              }
            }
          ]
        }
        Transform {
          translation 0 0 0.45
          rotation 1 0 0 2.3561996938995744
          children [
            Shape {
              appearance USE SECONDCOlOR
              geometry Box {
                size 0.01 1.34 0.07
              }
            }
          ]
        }
      ]
    }
  ]
  name "solid(1)"
}
DEF SECONDFACE Solid {
  translation 0.44 0.55 0.495
  rotation 0 1 0 1.5707996938995747
  children [
    Group {
      children [
        Shape {
          appearance DEF THIRDCOLOR PBRAppearance {
            baseColor 0.6784313725490196 0.4980392156862745 0.6588235294117647
          }
          geometry Box {
            size 0.01 1 0.1
          }
        }
        Transform {
          translation 0 0 -0.89
          children [
            Shape {
              appearance USE THIRDCOLOR
              geometry Box {
                size 0.01 1 0.1
              }
            }
          ]
        }
        Transform {
          translation 0 -0.45000148152350783 -0.445
          rotation 1 0 0 1.5707996938995747
          children [
            Shape {
              appearance USE THIRDCOLOR
              geometry Box {
                size 0.01 0.79 0.1
              }
            }
          ]
        }
        Transform {
          translation 0 0.4499999663289532 -0.4390000000000567
          rotation 1 0 0 1.5707996938995747
          children [
            Shape {
              appearance USE THIRDCOLOR
              geometry Box {
                size 0.01 0.8 0.1
              }
            }
          ]
        }
        Transform {
          translation 0 0.016158327597101868 -0.4520278416794996
          rotation 1 0 0 2.3561996938995744
          children [
            Shape {
              appearance USE THIRDCOLOR
              geometry Box {
                size 0.01 1.3 0.07
              }
            }
          ]
        }
        Transform {
          translation 0 -0.012125984058543544 -0.4520278676378151
          rotation 1 0 0 3.926990306100426
          children [
            Shape {
              appearance USE THIRDCOLOR
              geometry Box {
                size 0.01 1.3 0.07
              }
            }
          ]
        }
      ]
    }
  ]
  name "solid(2)"
}
DEF THIRDFACE Solid {
  translation -0.495 0.55 -0.45
  children [
    Group {
      children [
        Shape {
          appearance DEF SECONDCOlOR PBRAppearance {
            baseColor 0.9882352941176471 0.9137254901960784 0.30980392156862746
          }
          geometry Box {
            size 0.01 1 0.1
          }
        }
        Transform {
          translation 0 0 0.9
          children [
            Shape {
              appearance USE SECONDCOlOR
              geometry Box {
                size 0.01 1 0.1
              }
            }
          ]
        }
        Transform {
          translation 0 -0.45 0.45
          children [
            Shape {
              appearance USE SECONDCOlOR
              geometry Box {
                size 0.01 0.1 0.8
              }
            }
          ]
        }
        Transform {
          translation 0 0.45 0.45000000000000007
          children [
            Shape {
              appearance USE SECONDCOlOR
              geometry Box {
                size 0.01 0.1 0.8
              }
            }
          ]
        }
        Transform {
          translation 0 0 0.45
          rotation 1 0 0 0.7853996938995746
          children [
            Shape {
              appearance USE SECONDCOlOR
              geometry Box {
                size 0.01 1.34 0.07
              }
            }
          ]
        }
        Transform {
          translation 0 0 0.45
          rotation 1 0 0 2.3561996938995744
          children [
            Shape {
              appearance USE SECONDCOlOR
              geometry Box {
                size 0.01 1.34 0.07
              }
            }
          ]
        }
      ]
    }
  ]
  name "solid(3)"
}
DEF FOURTHFACE Solid {
  translation 0.445 0.5500000000000003 -0.5000014815232245
  rotation 0 1 0 1.5707996938995747
  children [
    Group {
      children [
        Shape {
          appearance DEF THIRDCOLOR PBRAppearance {
            baseColor 0.6784313725490196 0.4980392156862745 0.6588235294117647
          }
          geometry Box {
            size 0.01 1 0.1
          }
        }
        Transform {
          translation 0 0 -0.89
          children [
            Shape {
              appearance USE THIRDCOLOR
              geometry Box {
                size 0.01 1 0.1
              }
            }
          ]
        }
        Transform {
          translation 0 -0.45000148152350783 -0.445
          rotation 1 0 0 1.5707996938995747
          children [
            Shape {
              appearance USE THIRDCOLOR
              geometry Box {
                size 0.01 0.79 0.1
              }
            }
          ]
        }
        Transform {
          translation 0 0.4499999663289532 -0.4390000000000567
          rotation 1 0 0 1.5707996938995747
          children [
            Shape {
              appearance USE THIRDCOLOR
              geometry Box {
                size 0.01 0.8 0.1
              }
            }
          ]
        }
        Transform {
          translation 0 0.016158327597101868 -0.4520278416794996
          rotation 1 0 0 2.3561996938995744
          children [
            Shape {
              appearance USE THIRDCOLOR
              geometry Box {
                size 0.01 1.3 0.07
              }
            }
          ]
        }
        Transform {
          translation 0 -0.012125984058543544 -0.4520278676378151
          rotation 1 0 0 3.926990306100426
          children [
            Shape {
              appearance USE THIRDCOLOR
              geometry Box {
                size 0.01 1.3 0.07
              }
            }
          ]
        }
      ]
    }
  ]
  name "solid(4)"
}
Solid {
  translation 0 1.6 0
  children [
    Group {
      children [
        Shape {
          appearance USE FIRSTCOLOR
          geometry Cylinder {
            height 1
            radius 0.05
          }
        }
        HingeJoint {
          jointParameters HingeJointParameters {
          }
        }
      ]
    }
  ]
  name "solid(5)"
}
